Workbook

Sheet BCTC du phong
B1: PL | C1: 2015 | D1: 2016 | E1: 2017 | F1: 2018 | G1: 2019 | H1: =G1+1 -> 2020 | I1: =H1+1 -> 2021 | J1: =I1+1 -> 2022 | K1: =J1+1 -> 2023 | L1: =K1+1 -> 2024
B3: 1. Doanh thu bán hàng và cung cấp dịch vụ | C3: 1401104952000 | D3: 1388396581000 | E3: 1363513240000 | F3: 1463997591000 | G3: 1533850591000
B4: 2. Các khoản giảm trừ doanh thu | C4: 167074129000 | D4: 99102404000 | E4: 23862652000 | F4: 78909100000 | G4: 65460281000
B5: 3. Doanh thu thuần về bán hàng và cung cấp dịch vụ | C5: 1234030823000 | D5: 1289294177000 | E5: 1339650588000 | F5: 1385088491000 | G5: 1468390310000 | H5: ='Doanh thu'!G6 -> 1431668465000 | I5: ='Doanh thu'!H6 -> 1563811851000 | J5: ='Doanh thu'!I6 -> 1792864991400 | K5: ='Doanh thu'!J6 -> 2.1531865e+12 | L5: ='Doanh thu'!K6 -> 2.6933192e+12
B6: 4. Giá vốn hàng bán | C6: 824272566000 | D6: 790585526000 | E6: 804867972000 | F6: 896095667000 | G6: 975656508000 | H6: ='Doanh thu'!G17 -> 9.1436281e+11 | I6: ='Doanh thu'!H17 -> 9.9875875e+11 | J6: ='Doanh thu'!I17 -> 1.145048e+12 | K6: ='Doanh thu'!J17 -> 1.3751743e+12 | L6: ='Doanh thu'!K17 -> 1.7201405e+12
B7: 5. Lợi nhuận gộp về bán hàng và cung cấp dịch vụ | C7: 409758257000 | D7: 498708651000 | E7: 534782616000 | F7: 488992824000 | G7: 492733802000 | H7: =H5-H6 -> 5.1730565e+11 | I7: =I5-I6 -> 5.650531e+11 | J7: =J5-J6 -> 6.4781702e+11 | K7: =K5-K6 -> 7.7801223e+11 | L7: =L5-L6 -> 9.7317868e+11
B8: 6.Doanh thu hoạt động tài chính | C8: 2069445000 | D8: 9650395000 | E8: 15862747000 | F8: 21072474000 | G8: 20007170000 | H8: ='DT&CP tài chính'!G3 -> 1.9088173e+10 | I8: ='DT&CP tài chính'!H3 -> 3.6491415e+10 | J8: ='DT&CP tài chính'!I3 -> 3.3596774e+10 | K8: ='DT&CP tài chính'!J3 -> 4.7407019e+10 | L8: ='DT&CP tài chính'!K3 -> 4.065668e+10
B9: 7. Chi phí tài chính | C9: 2753785000 | D9: 6712827000 | E9: -595617000 | F9: 2523401000 | G9: 1353416000 | H9: ='DT&CP tài chính'!G4 -> 1.3091126e+09 | I9: ='DT&CP tài chính'!H4 -> 1.901854e+09 | J9: ='DT&CP tài chính'!I4 -> 1.785608e+09 | K9: ='DT&CP tài chính'!J4 -> 2.6497366e+09 | L9: ='DT&CP tài chính'!K4 -> 2.905354e+09
B10: Trong đó :Chi phí lãi vay | C10: 0 | D10: 0 | E10: 0 | F10: 203969000 | G10: 1159334000 | H10: ='DT&CP tài chính'!G15 -> 1.3091126e+09 | I10: ='DT&CP tài chính'!H15 -> 1.901854e+09 | J10: ='DT&CP tài chính'!I15 -> 1.785608e+09 | K10: ='DT&CP tài chính'!J15 -> 2.6497366e+09 | L10: ='DT&CP tài chính'!K15 -> 2.905354e+09
B11: 8. Phần lãi/lỗ trong công ty liên doanh, liên kết | C11: 0 | D11: 0 | E11: 0 | F11: 0 | G11: 0 | H11: =AVERAGE(E11:G11) -> 0 | I11: =H11 -> 0 | J11: =I11 -> 0 | K11: =J11 -> 0 | L11: =K11 -> 0
B12: 9. Chi phí bán hàng | C12: 143319798000 | D12: 195847520000 | E12: 197567030000 | F12: 138614540000 | G12: 145891689000 | H12: ='Doanh thu'!G20 -> 1.7608095e+11 | I12: ='Doanh thu'!H20 -> 1.9233326e+11 | J12: ='Doanh thu'!I20 -> 2.2050452e+11 | K12: ='Doanh thu'!J20 -> 2.6482048e+11 | L12: ='Doanh thu'!K20 -> 3.312514e+11
B13: 10. Chi phí quản lý doanh nghiệp | C13: 82089832000 | D13: 95762726000 | E13: 96853457000 | F13: 86454724000 | G13: 79894674000 | H13: ='Doanh thu'!G23 -> 9.4467916e+10 | I13: ='Doanh thu'!H23 -> 1.0318733e+11 | J13: ='Doanh thu'!I23 -> 1.1830129e+11 | K13: ='Doanh thu'!J23 -> 1.4207692e+11 | L13: ='Doanh thu'!K23 -> 1.777173e+11
B14: 11. Lợi nhuận thuần từ hoạt động kinh doanh | C14: 183664286000 | D14: 210035975000 | E14: 256820495000 | F14: 282472633000 | G14: 285601192000 | H14: =H7+H8-H9+H11-H12-H13 -> 2.6453585e+11 | I14: =I7+I8-I9+I11-I12-I13 -> 3.0412207e+11 | J14: =J7+J8-J9+J11-J12-J13 -> 3.4082238e+11 | K14: =K7+K8-K9+K11-K12-K13 -> 4.1587212e+11 | L14: =L7+L8-L9+L11-L12-L13 -> 5.0196131e+11
B15: 12. Thu nhập khác | C15: 1551102000 | D15: 1044907000 | E15: 3675965000 | F15: 3792368000 | G15: 5375202000 | H15: 5375202000 | I15: 5375202000 | J15: 5375202000 | K15: 5375202000 | L15: 5375202000
B16: 13. Chi phí khác | C16: 2002468000 | D16: 1183963000 | E16: 834453000 | F16: 175392000 | G16: 60781000 | H16: 60781000 | I16: 60781000 | J16: 60781000 | K16: 60781000 | L16: 60781000
B17: 14. Lợi nhuận khác | C17: -451366000 | D17: -139056000 | E17: 2841512000 | F17: 3616976000 | G17: 5314421000 | H17: =H15-H16 -> 5314421000 | I17: =I15-I16 -> 5314421000 | J17: =J15-J16 -> 5314421000 | K17: =K15-K16 -> 5314421000 | L17: =L15-L16 -> 5314421000
B18: 15. Tổng lợi nhuận kế toán trước thuế | C18: 183212920000 | D18: 209896919000 | E18: 259662006000 | F18: 286089609000 | G18: 290915613000 | H18: =H14+H17 -> 2.6985027e+11 | I18: =I14+I17 -> 3.0943649e+11 | J18: =J14+J17 -> 3.461368e+11 | K18: =K14+K17 -> 4.2118654e+11 | L18: =L14+L17 -> 5.0727573e+11
B19: 16. Chi phí thuế TNDN hiện hành | C19: 39198931000 | D19: 44555533000 | E19: 55541499000 | F19: 52285625000 | G19: 54386519000 | H19: =H18*H20 -> 5.0448365e+10 | I19: =I18*I20 -> 5.7848988e+10 | J19: =J18*J20 -> 6.4710091e+10 | K19: =K18*K20 -> 7.8740599e+10 | L19: =L18*L20 -> 9.4834928e+10
B20: Thuế suất | C20: 0.21395288 | D20: 0.2122734 | E20: 0.21389921 | F20: 0.18275961 | G20: 0.18694947 | H20: =G20 -> 0.18694947 | I20: =H20 -> 0.18694947 | J20: =I20 -> 0.18694947 | K20: =J20 -> 0.18694947 | L20: =K20 -> 0.18694947
B21: 17. Chi phí thuế TNDN hoãn lại | C21: 2454709000 | D21: -3300089000 | E21: -3541456000 | F21: 5032336000 | G21: 3894501000 | H21: 0 | I21: 0 | J21: 0 | K21: 0 | L21: 0
B22: 18. Lợi nhuận sau thuế thu nhập doanh nghiệp | C22: 141559279000 | D22: 168641475000 | E22: 207661963000 | F22: 228771647000 | G22: 232634592000 | H22: =H18-H19 -> 2.1940191e+11 | I22: =I18-I19 -> 2.515875e+11 | J22: =J18-J19 -> 2.8142671e+11 | K22: =K18-K19 -> 3.4244594e+11 | L22: =L18-L19 -> 4.124408e+11
B23: Lợi ích của cổ đông thiểu số | C23: 0 | D23: 0 | E23: 0 | F23: 0 | G23: 0 | H23: =H22*H24 -> 0 | I23: =I22*I24 -> 0 | J23: =J22*J24 -> 0 | K23: =K22*K24 -> 0 | L23: =L22*L24 -> 0
B24: % LNST | E24: 0 | F24: 0 | G24: 0 | H24: =G24 -> 0 | I24: =H24 -> 0 | J24: =I24 -> 0 | K24: =J24 -> 0 | L24: =K24 -> 0
B25: Lợi nhuận sau thuế của cổ đông của Công ty mẹ | C25: 141559279000 | D25: 168641475000 | E25: 207661963000 | F25: 228771647000 | G25: 232634592000 | H25: =H22-H23 -> 2.1940191e+11 | I25: =I22-I23 -> 2.515875e+11 | J25: =J22-J23 -> 2.8142671e+11 | K25: =K22-K23 -> 3.4244594e+11 | L25: =L22-L23 -> 4.124408e+11
H26: =IFERROR(LN(H25/G25),0) -> -0.058563705 | I26: =IFERROR(LN(I25/H25),0) -> 0.13688562 | J26: =IFERROR(LN(J25/I25),0) -> 0.1120812 | K26: =IFERROR(LN(K25/J25),0) -> 0.19624173 | L26: =IFERROR(LN(L25/K25),0) -> 0.18597889
B27: 19. Lãi cơ bản trên cổ phiếu (*) (VNÐ) | C27: 4374000 | D27: 4856000 | E27: 5980000 | F27: 6588000 | G27: 6699000 | H27: =H25/('Vốn CSH'!G4/10^4) -> 6317.821 | I27: =I25/('Vốn CSH'!H4/10^4) -> 7244.6263 | J27: =J25/('Vốn CSH'!I4/10^4) -> 8103.8657 | K27: =K25/('Vốn CSH'!J4/10^4) -> 9860.9541 | L27: =L25/('Vốn CSH'!K4/10^4) -> 11876.502
L28: 0
B30: BS | C30: 2015 | D30: 2016 | E30: 2017 | F30: 2018 | G30: 2019 | H30: =G30+1 -> 2020 | I30: =H30+1 -> 2021 | J30: =I30+1 -> 2022 | K30: =J30+1 -> 2023 | L30: =K30+1 -> 2024
B32: TÀI SẢN | H32: =H41+H50+H53-G41-G50-G53 -> -1.4849014e+11 | I32: =H32-H99 -> -1.4849014e+11 | L32: 0
B33: A. TÀI SẢN NGẮN HẠN | C33: 719994108000 | D33: 842929797000 | E33: 1079210647000 | F33: 1231691824000 | G33: 1298541565000 | H33: =H34+H37+H41+H50+H53 -> 1.4492753e+12 | I33: =I34+I37+I41+I50+I53 -> 1.7170271e+12 | J33: =J34+J37+J41+J50+J53 -> 1.9212314e+12 | K33: =K34+K37+K41+K50+K53 -> 2.2860036e+12 | L33: =L34+L37+L41+L50+L53 -> 2.6223265e+12
B34: I. Tiền và các khoản tương đương tiền | C34: 135164016000 | D34: 92319494000 | E34: 158731379000 | F34: 79508403000 | G34: 98367152000 | H34: =H323 -> 3.9759099e+11 | I34: =I323 -> 3.5034249e+11 | J34: =J323 -> 5.9295374e+11 | K34: =K323 -> 4.8381289e+11 | L34: =L323 -> 6.4089226e+11
B35: 1. Tiền | C35: 55128460000 | D35: 72319494000 | E35: 88731379000 | F35: 79508403000 | G35: 98367152000 | L35: 0
B36: 2. Các khoản tương đương tiền | C36: 80035556000 | D36: 20000000000 | E36: 70000000000 | F36: 0 | G36: 0 | L36: 0
B37: II. Đầu tư tài chính ngắn hạn | C37: 0 | D37: 115000000000 | E37: 270000000000 | F37: 290000000000 | G37: 260000000000 | H37: =G37 -> 260000000000 | I37: =H37 -> 260000000000 | J37: =I37 -> 260000000000 | K37: =J37 -> 260000000000 | L37: =K37 -> 260000000000
B38: 1. Chứng khoán kinh doanh | C38: 0 | D38: 0 | E38: 0 | F38: 0 | G38: 0 | H38: =G38 -> 0 | I38: =H38 -> 0 | J38: =I38 -> 0 | K38: =J38 -> 0 | L38: =K38 -> 0
B39: 2. Dự phòng giảm giá chứng khoán kinh doanh (*) | C39: 0 | D39: 0 | E39: 0 | F39: 0 | G39: 0 | H39: =G39 -> 0 | I39: =H39 -> 0 | J39: =I39 -> 0 | K39: =J39 -> 0 | L39: =K39 -> 0
B40: 3. Đầu tư nắm giữ đến ngày đáo hạn | C40: 0 | D40: 115000000000 | E40: 270000000000 | F40: 290000000000 | G40: 260000000000 | H40: =G40 -> 260000000000 | I40: =H40 -> 260000000000 | J40: =I40 -> 260000000000 | K40: =J40 -> 260000000000 | L40: =K40 -> 260000000000
B41: III. Các khoản phải thu ngắn hạn | C41: 305862812000 | D41: 311307010000 | E41: 400550889000 | F41: 585386459000 | G41: 717170550000 | H41: =SUM(H42:H49) -> 5.4849209e+11 | I41: =SUM(I42:I49) -> 8.3766135e+11 | J41: =SUM(J42:J49) -> 7.504514e+11 | K41: =SUM(K42:K49) -> 1.1556546e+12 | L41: =SUM(L42:L49) -> 1.2273671e+12
B42: 1. Phải thu ngắn hạn của khách hàng | C42: 289981415000 | D42: 300890087000 | E42: 380536847000 | F42: 555099634000 | G42: 699943710000 | H42: ='Vốn lưu động'!G4 -> 5.2371322e+11 | I42: ='Vốn lưu động'!H4 -> 8.1288758e+11 | J42: ='Vốn lưu động'!I4 -> 7.1948652e+11 | K42: ='Vốn lưu động'!J4 -> 1.1208569e+12 | L42: ='Vốn lưu động'!K4 -> 1.1811416e+12
B43: 2. Trả trước cho người bán ngắn hạn | C43: 1577897000 | D43: 1337079000 | E43: 3593154000 | F43: 9521850000 | G43: 7128949000 | H43: ='Vốn lưu động'!G7 -> 8.4757964e+09 | I43: ='Vốn lưu động'!H7 -> 8.5692712e+09 | J43: ='Vốn lưu động'!I7 -> 1.0972405e+10 | K43: ='Vốn lưu động'!J7 -> 1.2496665e+10 | L43: ='Vốn lưu động'!K7 -> 1.6859684e+10
...

Sheet Doanh thu
A1: I/ Dự phóng doanh thu | B1: ='[1]BC Kết Quả Kinh Doanh'!C5 -> 2015 | C1: ='[1]BC Kết Quả Kinh Doanh'!D5 -> 2016 | D1: ='[1]BC Kết Quả Kinh Doanh'!E5 -> 2017 | E1: ='[1]BC Kết Quả Kinh Doanh'!F5 -> 2018 | F1: ='[1]BC Kết Quả Kinh Doanh'!G5 -> 2019 | G1: =F1+1 -> 2020 | H1: =G1+1 -> 2021 | I1: =H1+1 -> 2022 | J1: =I1+1 -> 2023 | K1: =J1+1 -> 2024
A2: "Sheet này các bạn trình bày cách dự phóng doanh thu của mình vào nhé!"
A3: " Cách hiện tại đang dự phóng theo trend và tốc độ tăng trưởng của doanh nghiệp trong quá khứ"
A6: Doanh thu thuần | B6: ='BCTC du phong'!C5 -> 1234030823000 | C6: ='BCTC du phong'!D5 -> 1289294177000 | D6: ='BCTC du phong'!E5 -> 1339650588000 | E6: ='BCTC du phong'!F5 -> 1385088491000 | F6: ='BCTC du phong'!G5 -> 1468390310000 | G6: =G10+G13 -> 1431668465000 | H6: =H10+H13 -> 1563811851000 | I6: =I10+I13 -> 1792864991400 | J6: =J10+J13 -> 2.1531865e+12 | K6: =K10+K13 -> 2.6933192e+12
A7: % tăng trưởng | C7: =IFERROR(C6/B6-1,0) -> 0.044782799 | D7: =IFERROR(D6/C6-1,0) -> 0.039057348 | E7: =IFERROR(E6/D6-1,0) -> 0.033917727 | F7: =IFERROR(F6/E6-1,0) -> 0.060141875 | G7: =IFERROR(G6/F6-1,0) -> -0.025008232 | H7: =IFERROR(H6/G6-1,0) -> 0.09230027 | I7: =IFERROR(I6/H6-1,0) -> 0.14647104 | J7: =IFERROR(J6/I6-1,0) -> 0.20097529 | K7: =IFERROR(K6/J6-1,0) -> 0.25085268
A9: Doanh thu bán hàng thành phẩm
B10: 1023390000000 | C10: =1146270000000 -> 1146270000000 | D10: 1155730000000 | E10: 1159550000000 | F10: 1101310000000 | G10: =F10*(1+G11) -> 881048000000 | H10: =G10*(1+H11) -> 792943200000 | I10: =H10*(1+I11) -> 713648880000 | J10: =I10*(1+J11) -> 642283992000 | K10: =J10*(1+K11) -> 578055592800
A11: % tăng trưởng | C11: =C10/B10-1 -> 0.12007153 | D11: =D10/C10-1 -> 0.0082528549 | E11: =E10/D10-1 -> 0.0033052703 | F11: =F10/E10-1 -> -0.050226381 | G11: -0.2 | H11: -0.1 | I11: =H11 -> -0.1 | J11: =I11 -> -0.1 | K11: =J11 -> -0.1
A12: Doanh thu bán hàng hóa
B13: =B6-B10 -> 210640823000 | C13: =C6-C10 -> 143024177000 | D13: =D6-D10 -> 183920588000 | E13: =E6-E10 -> 225538491000 | F13: =F6-F10 -> 367080310000 | G13: =F13*(1+G14) -> 550620465000 | H13: =G13*(1+H14) -> 770868651000 | I13: =H13*(1+I14) -> 1.0792161e+12 | J13: =I13*(1+J14) -> 1.5109026e+12 | K13: =J13*(1+K14) -> 2.1152636e+12
A14: % tăng trưởng | C14: =C13/B13-1 -> -0.32100447 | D14: =D13/C13-1 -> 0.28594054 | E14: =E13/D13-1 -> 0.22628192 | F14: =F13/E13-1 -> 0.62757279 | G14: 0.5 | H14: 0.4 | I14: =H14 -> 0.4 | J14: =I14 -> 0.4 | K14: =J14 -> 0.4
A16: II/ Dự phóng giá vốn
A17: Giá vốn | B17: ='BCTC du phong'!C6 -> 824272566000 | C17: ='BCTC du phong'!D6 -> 790585526000 | D17: ='BCTC du phong'!E6 -> 804867972000 | E17: ='BCTC du phong'!F6 -> 896095667000 | F17: ='BCTC du phong'!G6 -> 975656508000 | G17: =G18*G6 -> 9.1436281e+11 | H17: =H18*H6 -> 9.9875875e+11 | I17: =I18*I6 -> 1.145048e+12 | J17: =J18*J6 -> 1.3751743e+12 | K17: =K18*K6 -> 1.7201405e+12
A18: % doanh thu thuần | B18: =B17/B6 -> 0.66795136 | C18: =C17/C6 -> 0.6131925 | D18: =D17/D6 -> 0.6008044 | E18: =E17/E6 -> 0.64695915 | F18: =F17/F6 -> 0.66443949 | G18: =AVERAGE(B18:F18) -> 0.63866938 | H18: =G18 -> 0.63866938 | I18: =H18 -> 0.63866938 | J18: =I18 -> 0.63866938 | K18: =J18 -> 0.63866938
A20: CP bán hàng | B20: ='BCTC du phong'!C12 -> 143319798000 | C20: ='BCTC du phong'!D12 -> 195847520000 | D20: ='BCTC du phong'!E12 -> 197567030000 | E20: ='BCTC du phong'!F12 -> 138614540000 | F20: ='BCTC du phong'!G12 -> 145891689000 | G20: =G21*G6 -> 1.7608095e+11 | H20: =H21*H6 -> 1.9233326e+11 | I20: =I21*I6 -> 2.2050452e+11 | J20: =J21*J6 -> 2.6482048e+11 | K20: =K21*K6 -> 3.312514e+11
A21: % doanh thu | B21: =B20/B6 -> 0.11613956 | C21: =C20/C6 -> 0.1519029 | D21: =D20/D6 -> 0.14747654 | E21: =E20/E6 -> 0.10007631 | F21: =F20/F6 -> 0.099354843 | G21: =AVERAGE(B21:F21) -> 0.12299003 | H21: =G21 -> 0.12299003 | I21: =H21 -> 0.12299003 | J21: =I21 -> 0.12299003 | K21: =J21 -> 0.12299003
A23: CP quản lý DN | B23: ='BCTC du phong'!C13 -> 82089832000 | C23: ='BCTC du phong'!D13 -> 95762726000 | D23: ='BCTC du phong'!E13 -> 96853457000 | E23: ='BCTC du phong'!F13 -> 86454724000 | F23: ='BCTC du phong'!G13 -> 79894674000 | G23: =G24*G6 -> 9.4467916e+10 | H23: =H24*H6 -> 1.0318733e+11 | I23: =I24*I6 -> 1.1830129e+11 | J23: =J24*J6 -> 1.4207692e+11 | K23: =K24*K6 -> 1.777173e+11
A24: % doanh thu | B24: =B23/B6 -> 0.066521703 | C24: =C23/C6 -> 0.074275311 | D24: =D23/D6 -> 0.072297551 | E24: =E23/E6 -> 0.062418195 | F24: =F23/F6 -> 0.054409698 | G24: =AVERAGE(B24:F24) -> 0.065984492 | H24: =G24 -> 0.065984492 | I24: =H24 -> 0.065984492 | J24: =I24 -> 0.065984492 | K24: =J24 -> 0.065984492
A26: III/ Phân tích độ nhạy
A27: " Phân tích độ nhạy khi biên lãi gộp và phần bù rủi ro thị trường dao động"
A29: Phần bù rủi ro thị trường | B29: 0.1052 | C29: => | D29: WACC ~ | E29: ='Định giá'!C24 -> 0.111056
C31: Min | D31: Trung bình 3 năm gần nhất | E31: Trung bình cộng | F31: Trung bình 2 năm gần nhất | G31: Năm gần nhất | H31: Max
A32: Giá trị nội tại | B32: ='Định giá'!B6 -> 64583.265 | C32: =MIN(B18:F18) -> 0.6008044 | D32: =AVERAGE(D18:F18) -> 0.63740101 | E32: =AVERAGE(B18:F18) -> 0.63866938 | F32: =AVERAGE(E18:F18) -> 0.65569932 | G32: =F18 -> 0.66443949 | H32: =MAX(B18:F18) -> 0.66795136 | I32: Biên lãi gộp
B33: 0.1 | C33: 82180.784 | D33: 67320.832 | E33: 66805.815 | F33: 59890.856 | G33: 56341.933 | H33: 54915.948
B34: 0.12 | C34: 0.1 | D34: 0.1 | E34: 0.1 | F34: 0.1 | G34: 0.1 | H34: 0.1
B35: 0.16 | C35: 0.1 | D35: 0.1 | E35: 0.1 | F35: 0.1 | G35: 0.1 | H35: 0.1
B36: 0.18 | C36: 0.1 | D36: 0.1 | E36: 0.1 | F36: 0.1 | G36: 0.1 | H36: 0.1
B37: 0.2 | C37: 0.1 | D37: 0.1 | E37: 0.1 | F37: 0.1 | G37: 0.1 | H37: 0.1
B38: Phần bù rủi ro thị trường ( ERP)
B40: ='Định giá'!B4 -> 64583.265 | C40: 0.05 | D40: 0.1 | E40: 0.15 | F40: 0.2 | G40: 0.25 | H40: 0.3
B41: 0.1 | C41: 84242.04 | D41: 82057.732 | E41: 79873.424 | F41: 77689.115 | G41: 75504.807 | H41: 73320.498
B42: 0.12 | C42: 84242.04 | D42: 82057.732 | E42: 79873.424 | F42: 77689.115 | G42: 75504.807 | H42: 73320.498
B43: 0.16 | C43: 84242.04 | D43: 82057.732 | E43: 79873.424 | F43: 77689.115 | G43: 75504.807 | H43: 73320.498
B44: 0.18 | C44: 84242.04 | D44: 82057.732 | E44: 79873.424 | F44: 77689.115 | G44: 75504.807 | H44: 73320.498
B45: 0.2 | C45: 84242.04 | D45: 82057.732 | E45: 79873.424 | F45: 77689.115 | G45: 75504.807 | H45: 73320.498

Sheet Vốn lưu động
A1: TS ngắn hạn | B1: ='[1]Bảng Cân Đối Kế Toán'!C5 -> 2015 | C1: ='[1]Bảng Cân Đối Kế Toán'!D5 -> 2016 | D1: ='[1]Bảng Cân Đối Kế Toán'!E5 -> 2017 | E1: ='[1]Bảng Cân Đối Kế Toán'!F5 -> 2018 | F1: ='[1]Bảng Cân Đối Kế Toán'!G5 -> 2019 | G1: =F1+1 -> 2020 | H1: =G1+1 -> 2021 | I1: =H1+1 -> 2022 | J1: =I1+1 -> 2023 | K1: =J1+1 -> 2024
A3: ='BCTC du phong'!B41 -> III. Các khoản phải thu ngắn hạn | B3: ='BCTC du phong'!C41 -> 305862812000 | C3: ='BCTC du phong'!D41 -> 311307010000 | D3: ='BCTC du phong'!E41 -> 400550889000 | E3: ='BCTC du phong'!F41 -> 585386459000 | F3: ='BCTC du phong'!G41 -> 717170550000 | G3: =G4+G7+G10+G13+G16+G19+G22+G25 -> 5.4849209e+11 | H3: =H4+H7+H10+H13+H16+H19+H22+H25 -> 8.3766135e+11 | I3: =I4+I7+I10+I13+I16+I19+I22+I25 -> 7.504514e+11 | J3: =J4+J7+J10+J13+J16+J19+J22+J25 -> 1.1556546e+12 | K3: =K4+K7+K10+K13+K16+K19+K22+K25 -> 1.2273671e+12
A4: ='BCTC du phong'!B42 -> 1. Phải thu ngắn hạn của khách hàng | B4: ='BCTC du phong'!C42 -> 289981415000 | C4: ='BCTC du phong'!D42 -> 300890087000 | D4: ='BCTC du phong'!E42 -> 380536847000 | E4: ='BCTC du phong'!F42 -> 555099634000 | F4: ='BCTC du phong'!G42 -> 699943710000 | G4: ='BCTC du phong'!H$5/'Vốn lưu động'!G5*2-'Vốn lưu động'!F4 -> 5.2371322e+11 | H4: ='BCTC du phong'!I$5/'Vốn lưu động'!H5*2-'Vốn lưu động'!G4 -> 8.1288758e+11 | I4: ='BCTC du phong'!J$5/'Vốn lưu động'!I5*2-'Vốn lưu động'!H4 -> 7.1948652e+11 | J4: ='BCTC du phong'!K$5/'Vốn lưu động'!J5*2-'Vốn lưu động'!I4 -> 1.1208569e+12 | K4: ='BCTC du phong'!L$5/'Vốn lưu động'!K5*2-'Vốn lưu động'!J4 -> 1.1811416e+12
A5: Vòng quay phải thu | C5: ='BCTC du phong'!D5/AVERAGE('Vốn lưu động'!B4:C4) -> 4.3640425 | D5: ='BCTC du phong'!E5/AVERAGE('Vốn lưu động'!C4:D4) -> 3.931898 | E5: ='BCTC du phong'!F5/AVERAGE('Vốn lưu động'!D4:E4) -> 2.9607407 | F5: ='BCTC du phong'!G5/AVERAGE('Vốn lưu động'!E4:F4) -> 2.3399834 | G5: =F5 -> 2.3399834 | H5: =G5 -> 2.3399834 | I5: =H5 -> 2.3399834 | J5: =I5 -> 2.3399834 | K5: =J5 -> 2.3399834
A7: ='BCTC du phong'!B43 -> 2. Trả trước cho người bán ngắn hạn | B7: ='BCTC du phong'!C43 -> 1577897000 | C7: ='BCTC du phong'!D43 -> 1337079000 | D7: ='BCTC du phong'!E43 -> 3593154000 | E7: ='BCTC du phong'!F43 -> 9521850000 | F7: ='BCTC du phong'!G43 -> 7128949000 | G7: ='BCTC du phong'!H$6/'Vốn lưu động'!G8*2-'Vốn lưu động'!F7 -> 8.4757964e+09 | H7: ='BCTC du phong'!I$6/'Vốn lưu động'!H8*2-'Vốn lưu động'!G7 -> 8.5692712e+09 | I7: ='BCTC du phong'!J$6/'Vốn lưu động'!I8*2-'Vốn lưu động'!H7 -> 1.0972405e+10 | J7: ='BCTC du phong'!K$6/'Vốn lưu động'!J8*2-'Vốn lưu động'!I7 -> 1.2496665e+10 | K7: ='BCTC du phong'!L$6/'Vốn lưu động'!K8*2-'Vốn lưu động'!J7 -> 1.6859684e+10
A8: Vòng quay trả trước người bán | C8: ='BCTC du phong'!D$6/AVERAGE('Vốn lưu động'!B7:C7) -> 542.43021 | D8: ='BCTC du phong'!E$6/AVERAGE('Vốn lưu động'!C7:D7) -> 326.50302 | E8: ='BCTC du phong'!F$6/AVERAGE('Vốn lưu động'!D7:E7) -> 136.65199 | F8: ='BCTC du phong'!G$6/AVERAGE('Vốn lưu động'!E7:F7) -> 117.19035 | G8: =F8 -> 117.19035 | H8: =G8 -> 117.19035 | I8: =H8 -> 117.19035 | J8: =I8 -> 117.19035 | K8: =J8 -> 117.19035
G9: =">="&MIN(C8:F8) -> >=117,190353207675 | H9: ="<"&MIN(C8:F8)*10 -> <1171,90353207675
A10: ='BCTC du phong'!B44 -> 3. Phải thu nội bộ ngắn hạn | B10: ='BCTC du phong'!C44 -> 0 | C10: ='BCTC du phong'!D44 -> 0 | D10: ='BCTC du phong'!E44 -> 0 | E10: ='BCTC du phong'!F44 -> 0 | F10: ='BCTC du phong'!G44 -> 0 | G10: =G11*'BCTC du phong'!H$5 -> 0 | H10: =H11*'BCTC du phong'!I$5 -> 0 | I10: =I11*'BCTC du phong'!J$5 -> 0 | J10: =J11*'BCTC du phong'!K$5 -> 0 | K10: =K11*'BCTC du phong'!L$5 -> 0
A11: % doanh thu | B11: =IFERROR(B10/'BCTC du phong'!C$5,0) -> 0 | C11: =IFERROR(C10/'BCTC du phong'!D$5,0) -> 0 | D11: =IFERROR(D10/'BCTC du phong'!E$5,0) -> 0 | E11: =IFERROR(E10/'BCTC du phong'!F$5,0) -> 0 | F11: =IFERROR(F10/'BCTC du phong'!G$5,0) -> 0 | G11: =AVERAGE(E11:F11) -> 0 | H11: =G11 -> 0 | I11: =H11 -> 0 | J11: =I11 -> 0 | K11: =J11 -> 0
A13: ='BCTC du phong'!B45 -> 4. Phải thu theo tiến độ kế hoạch hợp đồng xây dựng | B13: ='BCTC du phong'!C45 -> 0 | C13: ='BCTC du phong'!D45 -> 0 | D13: ='BCTC du phong'!E45 -> 0 | E13: ='BCTC du phong'!F45 -> 0 | F13: ='BCTC du phong'!G45 -> 0 | G13: =G14*'BCTC du phong'!H$5 -> 0 | H13: =H14*'BCTC du phong'!I$5 -> 0 | I13: =I14*'BCTC du phong'!J$5 -> 0 | J13: =J14*'BCTC du phong'!K$5 -> 0 | K13: =K14*'BCTC du phong'!L$5 -> 0
A14: % doanh thu | B14: =IFERROR(B13/'BCTC du phong'!C$5,0) -> 0 | C14: =IFERROR(C13/'BCTC du phong'!D$5,0) -> 0 | D14: =IFERROR(D13/'BCTC du phong'!E$5,0) -> 0 | E14: =IFERROR(E13/'BCTC du phong'!F$5,0) -> 0 | F14: =IFERROR(F13/'BCTC du phong'!G$5,0) -> 0 | G14: =AVERAGE(E14:F14) -> 0 | H14: =G14 -> 0 | I14: =H14 -> 0 | J14: =I14 -> 0 | K14: =J14 -> 0
A16: ='BCTC du phong'!B46 -> 5. Phải thu về cho vay ngắn hạn | B16: ='BCTC du phong'!C46 -> 0 | C16: ='BCTC du phong'!D46 -> 0 | D16: ='BCTC du phong'!E46 -> 0 | E16: ='BCTC du phong'!F46 -> 0 | F16: ='BCTC du phong'!G46 -> 0 | G16: =G17*'BCTC du phong'!H$5 -> 0 | H16: =H17*'BCTC du phong'!I$5 -> 0 | I16: =I17*'BCTC du phong'!J$5 -> 0 | J16: =J17*'BCTC du phong'!K$5 -> 0 | K16: =K17*'BCTC du phong'!L$5 -> 0
A17: % doanh thu | B17: =IFERROR(B16/'BCTC du phong'!C$5,0) -> 0 | C17: =IFERROR(C16/'BCTC du phong'!D$5,0) -> 0 | D17: =IFERROR(D16/'BCTC du phong'!E$5,0) -> 0 | E17: =IFERROR(E16/'BCTC du phong'!F$5,0) -> 0 | F17: =IFERROR(F16/'BCTC du phong'!G$5,0) -> 0 | G17: =AVERAGE(E17:F17) -> 0 | H17: =G17 -> 0 | I17: =H17 -> 0 | J17: =I17 -> 0 | K17: =J17 -> 0
A19: ='BCTC du phong'!B47 -> 6. Phải thu ngắn hạn khác | B19: ='BCTC du phong'!C47 -> 19179287000 | C19: ='BCTC du phong'!D47 -> 14607612000 | D19: ='BCTC du phong'!E47 -> 19092372000 | E19: ='BCTC du phong'!F47 -> 24932746000 | F19: ='BCTC du phong'!G47 -> 14154382000 | G19: =G20*'BCTC du phong'!H$5 -> 1.9785815e+10 | H19: =H20*'BCTC du phong'!I$5 -> 2.1612051e+10 | I19: =I20*'BCTC du phong'!J$5 -> 2.4777591e+10 | J19: =J20*'BCTC du phong'!K$5 -> 2.9757274e+10 | K19: =K20*'BCTC du phong'!L$5 -> 3.7221966e+10
A20: % doanh thu | B20: =IFERROR(B19/'BCTC du phong'!C$5,0) -> 0.015541984 | C20: =IFERROR(C19/'BCTC du phong'!D$5,0) -> 0.011329929 | D20: =IFERROR(D19/'BCTC du phong'!E$5,0) -> 0.014251755 | E20: =IFERROR(E19/'BCTC du phong'!F$5,0) -> 0.018000833 | F20: =IFERROR(F19/'BCTC du phong'!G$5,0) -> 0.0096393867 | G20: =AVERAGE(E20:F20) -> 0.01382011 | H20: =G20 -> 0.01382011 | I20: =H20 -> 0.01382011 | J20: =I20 -> 0.01382011 | K20: =J20 -> 0.01382011
A22: ='BCTC du phong'!B48 -> 7. Dự phòng phải thu ngắn hạn khó đòi (*) | B22: ='BCTC du phong'!C48 -> -4875787000 | C22: ='BCTC du phong'!D48 -> -5527768000 | D22: ='BCTC du phong'!E48 -> -2671484000 | E22: ='BCTC du phong'!F48 -> -4167772000 | F22: ='BCTC du phong'!G48 -> -4064415000 | G22: =-G23*G4 -> -3.4866012e+09 | H22: =-H23*H4 -> -5.4117687e+09 | I22: =-I23*I4 -> -4.7899546e+09 | J22: =-J23*J4 -> -7.462063e+09 | K22: =-K23*K4 -> -7.8634061e+09
A23: % khoản phải thu | B23: =-B22/B4 -> 0.016814136 | C23: =-C22/C4 -> 0.018371386 | D23: =-D22/D4 -> 0.0070203031 | E23: =-E22/E4 -> 0.0075081512 | F23: =-F22/F4 -> 0.0058067741 | G23: =AVERAGE(E23:F23) -> 0.0066574627 | H23: =G23 -> 0.0066574627 | I23: =H23 -> 0.0066574627 | J23: =I23 -> 0.0066574627 | K23: =J23 -> 0.0066574627
A25: ='BCTC du phong'!B49 -> 8. Tài sản thiếu chờ xử lý | B25: ='BCTC du phong'!C49 -> 0 | C25: ='BCTC du phong'!D49 -> 0 | D25: ='BCTC du phong'!E49 -> 0 | E25: ='BCTC du phong'!F49 -> 0 | F25: ='BCTC du phong'!G49 -> 7924000 | G25: =G26*'BCTC du phong'!H$5 -> 3862917.4 | H25: =H26*'BCTC du phong'!I$5 -> 4219465.7 | I25: =I26*'BCTC du phong'!J$5 -> 4837495.2 | J25: =J26*'BCTC du phong'!K$5 -> 5809712.2 | K25: =K26*'BCTC du phong'!L$5 -> 7267094.1
A26: % doanh thu | B26: =IFERROR(B25/'BCTC du phong'!C$5,0) -> 0 | C26: =IFERROR(C25/'BCTC du phong'!D$5,0) -> 0 | D26: =IFERROR(D25/'BCTC du phong'!E$5,0) -> 0 | E26: =IFERROR(E25/'BCTC du phong'!F$5,0) -> 0 | F26: =IFERROR(F25/'BCTC du phong'!G$5,0) -> 5.3963854e-06 | G26: =AVERAGE(E26:F26) -> 2.6981927e-06 | H26: =G26 -> 2.6981927e-06 | I26: =H26 -> 2.6981927e-06 | J26: =I26 -> 2.6981927e-06 | K26: =J26 -> 2.6981927e-06
A28: ='BCTC du phong'!B50 -> IV. Hàng tồn kho | B28: ='BCTC du phong'!C50 -> 277343788000 | C28: ='BCTC du phong'!D50 -> 320318925000 | D28: ='BCTC du phong'!E50 -> 244889043000 | E28: ='BCTC du phong'!F50 -> 266490182000 | F28: ='BCTC du phong'!G50 -> 219139200000 | G28: =G29+G32 -> 2.3598147e+11 | H28: =H29+H32 -> 2.6114696e+11 | I28: =I29+I32 -> 3.0879639e+11 | J28: =J29+J32 -> 3.7569149e+11 | K28: =K29+K32 -> 4.8050201e+11
A29: ='BCTC du phong'!B51 -> 1. Hàng tồn kho | B29: ='BCTC du phong'!C51 -> 277921069000 | C29: ='BCTC du phong'!D51 -> 320318925000 | D29: ='BCTC du phong'!E51 -> 244889043000 | E29: ='BCTC du phong'!F51 -> 266490182000 | F29: ='BCTC du phong'!G51 -> 219139200000 | G29: ='BCTC du phong'!H$6/'Vốn lưu động'!G30*2-'Vốn lưu động'!F29 -> 2.3598147e+11 | H29: ='BCTC du phong'!I$6/'Vốn lưu động'!H30*2-'Vốn lưu động'!G29 -> 2.6114696e+11 | I29: ='BCTC du phong'!J$6/'Vốn lưu động'!I30*2-'Vốn lưu động'!H29 -> 3.0879639e+11 | J29: ='BCTC du phong'!K$6/'Vốn lưu động'!J30*2-'Vốn lưu động'!I29 -> 3.7569149e+11 | K29: ='BCTC du phong'!L$6/'Vốn lưu động'!K30*2-'Vốn lưu động'!J29 -> 4.8050201e+11
A30: Vòng quay HTK | C30: ='BCTC du phong'!D$6/AVERAGE('Vốn lưu động'!B29:C29) -> 2.643038 | D30: ='BCTC du phong'!E$6/AVERAGE('Vốn lưu động'!C29:D29) -> 2.8480418 | E30: ='BCTC du phong'!F$6/AVERAGE('Vốn lưu động'!D29:E29) -> 3.5046229 | F30: ='BCTC du phong'!G$6/AVERAGE('Vốn lưu động'!E29:F29) -> 4.0181115 | G30: =F30 -> 4.0181115 | H30: =G30 -> 4.0181115 | I30: =H30 -> 4.0181115 | J30: =I30 -> 4.0181115 | K30: =J30 -> 4.0181115
G31: =">="&MIN(C30:F30) -> >=2,64303802463598 | H31: ="<"&MIN(C30:F30)*10 -> <26,4303802463598
A32: ='BCTC du phong'!B52 -> 2. Dự phòng giảm giá hàng tồn kho (*) | B32: ='BCTC du phong'!C52 -> -577281000 | C32: ='BCTC du phong'!D52 -> 0 | D32: ='BCTC du phong'!E52 -> 0 | E32: ='BCTC du phong'!F52 -> 0 | F32: ='BCTC du phong'!G52 -> 0 | G32: =-G33*G29 -> 0 | H32: =-H33*H29 -> 0 | I32: =-I33*I29 -> 0 | J32: =-J33*J29 -> 0 | K32: =-K33*K29 -> 0
A33: % hàng tồn kho | B33: =-B32/B29 -> 0.0020771401 | C33: =-C32/C29 -> 0 | D33: =-D32/D29 -> 0 | E33: =-E32/E29 -> 0 | F33: =-F32/F29 -> 0 | G33: =AVERAGE(E33:F33) -> 0 | H33: =G33 -> 0 | I33: =H33 -> 0 | J33: =I33 -> 0 | K33: =J33 -> 0
A35: ='BCTC du phong'!B53 -> V. Tài sản ngắn hạn khác | B35: ='BCTC du phong'!C53 -> 1623493000 | C35: ='BCTC du phong'!D53 -> 3984368000 | D35: ='BCTC du phong'!E53 -> 5039336000 | E35: ='BCTC du phong'!F53 -> 10306780000 | F35: ='BCTC du phong'!G53 -> 3864663000 | G35: =G36+G39+G42+G45+G48 -> 7.2107043e+09 | H35: =H36+H39+H42+H45+H48 -> 7.8762542e+09 | I35: =I36+I39+I42+I45+I48 -> 9.0298973e+09 | J35: =J36+J39+J42+J45+J48 -> 1.0844684e+10 | K35: =K36+K39+K42+K45+K48 -> 1.3565102e+10
A36: ='BCTC du phong'!B54 -> 1. Chi phí trả trước ngắn hạn | B36: ='BCTC du phong'!C54 -> 1622172000 | C36: ='BCTC du phong'!D54 -> 3984368000 | D36: ='BCTC du phong'!E54 -> 4797474000 | E36: ='BCTC du phong'!F54 -> 8591455000 | F36: ='BCTC du phong'!G54 -> 3840044000 | G36: =G37*'BCTC du phong'!H$5 -> 6.3121967e+09 | H36: =H37*'BCTC du phong'!I$5 -> 6.8948142e+09 | I36: =I37*'BCTC du phong'!J$5 -> 7.9047048e+09 | J36: =J37*'BCTC du phong'!K$5 -> 9.4933551e+09 | K36: =K37*'BCTC du phong'!L$5 -> 1.1874789e+10
A37: % doanh thu | B37: =IFERROR(B36/'BCTC du phong'!C$5,0) -> 0.0013145312 | C37: =IFERROR(C36/'BCTC du phong'!D$5,0) -> 0.0030903482 | D37: =IFERROR(D36/'BCTC du phong'!E$5,0) -> 0.0035811383 | E37: =IFERROR(E36/'BCTC du phong'!F$5,0) -> 0.0062028203 | F37: =IFERROR(F36/'BCTC du phong'!G$5,0) -> 0.0026151385 | G37: =AVERAGE(E37:F37) -> 0.0044089794 | H37: =G37 -> 0.0044089794 | I37: =H37 -> 0.0044089794 | J37: =I37 -> 0.0044089794 | K37: =J37 -> 0.0044089794
A39: ='BCTC du phong'!B55 -> 2. Thuế GTGT được khấu trừ | B39: ='BCTC du phong'!C55 -> 0 | C39: ='BCTC du phong'!D55 -> 0 | D39: ='BCTC du phong'!E55 -> 0 | E39: ='BCTC du phong'!F55 -> 0 | F39: ='BCTC du phong'!G55 -> 0 | G39: =G40*'BCTC du phong'!H$5 -> 0 | H39: =H40*'BCTC du phong'!I$5 -> 0 | I39: =I40*'BCTC du phong'!J$5 -> 0 | J39: =J40*'BCTC du phong'!K$5 -> 0 | K39: =K40*'BCTC du phong'!L$5 -> 0
A40: % doanh thu | B40: =IFERROR(B39/'BCTC du phong'!C$5,0) -> 0 | C40: =IFERROR(C39/'BCTC du phong'!D$5,0) -> 0 | D40: =IFERROR(D39/'BCTC du phong'!E$5,0) -> 0 | E40: =IFERROR(E39/'BCTC du phong'!F$5,0) -> 0 | F40: =IFERROR(F39/'BCTC du phong'!G$5,0) -> 0 | G40: =AVERAGE(E40:F40) -> 0 | H40: =G40 -> 0 | I40: =H40 -> 0 | J40: =I40 -> 0 | K40: =J40 -> 0
A42: ='BCTC du phong'!B56 -> 3. Thuế và các khoản khác phải thu của nhà nước | B42: ='BCTC du phong'!C56 -> 1321000 | C42: ='BCTC du phong'!D56 -> 0 | D42: ='BCTC du phong'!E56 -> 241862000 | E42: ='BCTC du phong'!F56 -> 1715326000 | F42: ='BCTC du phong'!G56 -> 24619000 | G42: =G43*'BCTC du phong'!H$5 -> 8.9850753e+08 | H42: =H43*'BCTC du phong'!I$5 -> 9.8144001e+08 | I42: =I43*'BCTC du phong'!J$5 -> 1.1251925e+09 | J42: =J43*'BCTC du phong'!K$5 -> 1.3513284e+09 | K42: =K43*'BCTC du phong'!L$5 -> 1.6903128e+09
A43: % doanh thu | B43: =IFERROR(B42/'BCTC du phong'!C$5,0) -> 1.0704757e-06 | C43: =IFERROR(C42/'BCTC du phong'!D$5,0) -> 0 | D43: =IFERROR(D42/'BCTC du phong'!E$5,0) -> 0.00018054111 | E43: =IFERROR(E42/'BCTC du phong'!F$5,0) -> 0.0012384234 | F43: =IFERROR(F42/'BCTC du phong'!G$5,0) -> 1.6765978e-05 | G43: =AVERAGE(E43:F43) -> 0.00062759469 | H43: =G43 -> 0.00062759469 | I43: =H43 -> 0.00062759469 | J43: =I43 -> 0.00062759469 | K43: =J43 -> 0.00062759469
A45: ='BCTC du phong'!B57 -> 4. Giao dịch mua bán lại trái phiếu chính phủ | B45: ='BCTC du phong'!C57 -> 0 | C45: ='BCTC du phong'!D57 -> 0 | D45: ='BCTC du phong'!E57 -> 0 | E45: ='BCTC du phong'!F57 -> 0 | F45: ='BCTC du phong'!G57 -> 0 | G45: =G46*'BCTC du phong'!H$5 -> 0 | H45: =H46*'BCTC du phong'!I$5 -> 0 | I45: =I46*'BCTC du phong'!J$5 -> 0 | J45: =J46*'BCTC du phong'!K$5 -> 0 | K45: =K46*'BCTC du phong'!L$5 -> 0
A46: % doanh thu | B46: =IFERROR(B45/'BCTC du phong'!C$5,0) -> 0 | C46: =IFERROR(C45/'BCTC du phong'!D$5,0) -> 0 | D46: =IFERROR(D45/'BCTC du phong'!E$5,0) -> 0 | E46: =IFERROR(E45/'BCTC du phong'!F$5,0) -> 0 | F46: =IFERROR(F45/'BCTC du phong'!G$5,0) -> 0 | G46: =AVERAGE(E46:F46) -> 0 | H46: =G46 -> 0 | I46: =H46 -> 0 | J46: =I46 -> 0 | K46: =J46 -> 0
A48: ='BCTC du phong'!B58 -> 5. Tài sản ngắn hạn khác | B48: ='BCTC du phong'!C58 -> 0 | C48: ='BCTC du phong'!D58 -> 0 | D48: ='BCTC du phong'!E58 -> 0 | E48: ='BCTC du phong'!F58 -> 0 | F48: ='BCTC du phong'!G58 -> 0 | G48: =G49*'BCTC du phong'!H$5 -> 0 | H48: =H49*'BCTC du phong'!I$5 -> 0 | I48: =I49*'BCTC du phong'!J$5 -> 0 | J48: =J49*'BCTC du phong'!K$5 -> 0 | K48: =K49*'BCTC du phong'!L$5 -> 0
A49: % doanh thu | B49: =IFERROR(B48/'BCTC du phong'!C$5,0) -> 0 | C49: =IFERROR(C48/'BCTC du phong'!D$5,0) -> 0 | D49: =IFERROR(D48/'BCTC du phong'!E$5,0) -> 0 | E49: =IFERROR(E48/'BCTC du phong'!F$5,0) -> 0 | F49: =IFERROR(F48/'BCTC du phong'!G$5,0) -> 0 | G49: =AVERAGE(E49:F49) -> 0 | H49: =G49 -> 0 | I49: =H49 -> 0 | J49: =I49 -> 0 | K49: =J49 -> 0
A52: Nợ phải trả ngắn hạn (không kể vay ngắn hạn) | B52: =B54+B57+B60+B63+B72+B75+B78+B81+B69+B66 -> 192144266000 | C52: =C54+C57+C60+C63+C72+C75+C78+C81+C69+C66 -> 199291344000 | D52: =D54+D57+D60+D63+D72+D75+D78+D81+D69+D66 -> 349556194000 | E52: =E54+E57+E60+E63+E72+E75+E78+E81+E69+E66 -> 308702309000 | F52: =F54+F57+F60+F63+F72+F75+F78+F81+F69+F66 -> 272582295000 | G52: =G54+G57+G60+G63+G72+G75+G78+G81+G69+G66 -> 2.6240341e+11 | H52: =H54+H57+H60+H63+H72+H75+H78+H81+H69+H66 -> 3.3775537e+11 | I52: =I54+I57+I60+I63+I72+I75+I78+I81+I69+I66 -> 3.4634733e+11 | ... K52: =K54+K57+K60+K63+K72+K75+K78+K81+K69+K66 -> 5.4678491e+11
A54: ='BCTC du phong'!B103 -> 1. Phải trả người bán ngắn hạn | B54: ='BCTC du phong'!C103 -> 137615613000 | C54: ='BCTC du phong'!D103 -> 120021312000 | D54: ='BCTC du phong'!E103 -> 162270656000 | E54: ='BCTC du phong'!F103 -> 216705486000 | F54: ='BCTC du phong'!G103 -> 220083387000 | G54: ='BCTC du phong'!H$6/'Vốn lưu động'!G55*2-'Vốn lưu động'!F54 -> 1.8926509e+11 | H54: ='BCTC du phong'!I$6/'Vốn lưu động'!H55*2-'Vốn lưu động'!G54 -> 2.5786636e+11 | I54: ='BCTC du phong'!J$6/'Vốn lưu động'!I55*2-'Vốn lưu động'!H54 -> 2.5475689e+11 | J54: ='BCTC du phong'!K$6/'Vốn lưu động'!J55*2-'Vốn lưu động'!I54 -> 3.6089097e+11 | K54: ='BCTC du phong'!L$6/'Vốn lưu động'!K55*2-'Vốn lưu động'!J54 -> 4.0919381e+11
A55: Vòng quay phải trả người bán ngắn hạn | C55: ='BCTC du phong'!D6/AVERAGE('Vốn lưu động'!B54:C54) -> 6.1372067 | D55: ='BCTC du phong'!E6/AVERAGE('Vốn lưu động'!C54:D54) -> 5.7023795 | E55: ='BCTC du phong'!F6/AVERAGE('Vốn lưu động'!D54:E54) -> 4.7290347 | F55: ='BCTC du phong'!G6/AVERAGE('Vốn lưu động'!E54:F54) -> 4.4674055 | G55: =F55 -> 4.4674055 | H55: =G55 -> 4.4674055 | I55: =H55 -> 4.4674055 | J55: =I55 -> 4.4674055 | K55: =J55 -> 4.4674055
G56: =">="&MIN(C55:F55) -> >=4,46740550554272 | H56: ="<"&MIN(C55:F55)*10 -> <44,6740550554272
...

Sheet TSCĐ
A1: TSCĐ hữu hình | B1: ='[1]Bảng Cân Đối Kế Toán'!C5 -> 2015 | C1: ='[1]Bảng Cân Đối Kế Toán'!D5 -> 2016 | D1: ='[1]Bảng Cân Đối Kế Toán'!E5 -> 2017 | E1: ='[1]Bảng Cân Đối Kế Toán'!F5 -> 2018 | F1: ='[1]Bảng Cân Đối Kế Toán'!G5 -> 2019 | G1: =F1+1 -> 2020 | H1: =G1+1 -> 2021 | I1: =H1+1 -> 2022 | J1: =I1+1 -> 2023 | K1: =J1+1 -> 2024
A3: ='BCTC du phong'!B70 -> 1. Tài sản cố định hữu hình | B3: ='BCTC du phong'!C70 -> 191167289000 | C3: ='BCTC du phong'!D70 -> 169441402000 | D3: ='BCTC du phong'!E70 -> 152530989000 | E3: ='BCTC du phong'!F70 -> 137785852000 | F3: ='BCTC du phong'!G70 -> 152447776000 | G3: =G4+G5 -> 1.1565369e+11 | H3: =H4+H5 -> 9.2850241e+10 | I3: =I4+I5 -> 5.970396e+10 | J3: =J4+J5 -> 4.1050895e+10 | K3: =K4+K5 -> 1.6435001e+10
A4: ='BCTC du phong'!B71 -> - Nguyên giá | B4: ='BCTC du phong'!C71 -> 423377171000 | C4: ='BCTC du phong'!D71 -> 429045147000 | D4: ='BCTC du phong'!E71 -> 439723581000 | E4: ='BCTC du phong'!F71 -> 452084455000 | F4: ='BCTC du phong'!G71 -> 485880443000 | G4: =F4+G9+G8 -> 500488089000 | H4: =G4+H9+H8 -> 5.2780761e+11 | I4: =H4+I9+I8 -> 5.4283006e+11 | J4: =I4+J9+J8 -> 5.7112029e+11 | K4: =J4+K9+K8 -> 5.9180446e+11
A5: ='BCTC du phong'!B72 -> - Giá trị hao mòn lũy kế (*) | B5: ='BCTC du phong'!C72 -> -232209881000 | C5: ='BCTC du phong'!D72 -> -259603745000 | D5: ='BCTC du phong'!E72 -> -287192591000 | E5: ='BCTC du phong'!F72 -> -314298604000 | F5: ='BCTC du phong'!G72 -> -333432667000 | G5: =F5+G10 -> -3.848344e+11 | H5: =G5+H10 -> -4.3495736e+11 | I5: =H5+I10 -> -4.831261e+11 | J5: =I5+J10 -> -5.300694e+11 | K5: =J5+K10 -> -5.7536946e+11
A7: Đầu kì | C7: =B11 -> 191167289000 | D7: =C11 -> 169441402000 | E7: =D11 -> 152530989000 | F7: =E11 -> 137785852000 | G7: =F11 -> 152447776000 | H7: =G11 -> 1.1565369e+11 | I7: =H11 -> 9.2850241e+10 | J7: =I11 -> 5.970396e+10 | K7: =J11 -> 4.1050895e+10
A8: Tăng thêm
A9: Chuyển từ TSXDDD | G9: =-G31 -> 14607646000 | H9: =-H31 -> 2.7319517e+10 | I9: =-I31 -> 1.5022453e+10 | J9: =-J31 -> 2.8290233e+10 | K9: =-K31 -> 2.0684167e+10
A10: Khấu hao | C10: =-('[1]Bảng Cân Đối Kế Toán'!C45-'[1]Bảng Cân Đối Kế Toán'!D45) -> -27393864000 | D10: =-('[1]Bảng Cân Đối Kế Toán'!D45-'[1]Bảng Cân Đối Kế Toán'!E45) -> -27588846000 | E10: =-('[1]Bảng Cân Đối Kế Toán'!E45-'[1]Bảng Cân Đối Kế Toán'!F45) -> -27106013000 | F10: =-('[1]Bảng Cân Đối Kế Toán'!F45-'[1]Bảng Cân Đối Kế Toán'!G45) -> -19134063000 | G10: =-SUM(G18:G23) -> -5.1401728e+10 | H10: =-SUM(H18:H23) -> -5.012297e+10 | I10: =-SUM(I18:I23) -> -4.8168735e+10 | J10: =-SUM(J18:J23) -> -4.6943298e+10 | K10: =-SUM(K18:K23) -> -4.530006e+10
A11: Cuối kì | B11: =B3 -> 191167289000 | C11: =C3 -> 169441402000 | D11: =D3 -> 152530989000 | E11: =E3 -> 137785852000 | F11: =F3 -> 152447776000 | G11: =SUM(G7:G10) -> 1.1565369e+11 | H11: =SUM(H7:H10) -> 9.2850241e+10 | I11: =SUM(I7:I10) -> 5.970396e+10 | J11: =SUM(J7:J10) -> 4.1050895e+10 | K11: =SUM(K7:K10) -> 1.6435001e+10
A14: ='BCTC du phong'!B76 -> 3. Tài sản cố định vô hình | B14: ='BCTC du phong'!C76 -> 51455930000 | C14: ='BCTC du phong'!D76 -> 49644233000 | D14: ='BCTC du phong'!E76 -> 48396831000 | E14: ='BCTC du phong'!F76 -> 47859915000 | F14: ='BCTC du phong'!G76 -> 48075551000 | G14: =F14 -> 48075551000 | H14: =G14 -> 48075551000 | I14: =H14 -> 48075551000 | J14: =I14 -> 48075551000 | K14: =J14 -> 48075551000
A15: ='BCTC du phong'!B77 -> - Nguyên giá | B15: ='BCTC du phong'!C77 -> 57680854000 | C15: ='BCTC du phong'!D77 -> 57650854000 | D15: ='BCTC du phong'!E77 -> 57650854000 | E15: ='BCTC du phong'!F77 -> 58250854000 | F15: ='BCTC du phong'!G77 -> 59791814000
A16: ='BCTC du phong'!B78 -> - Giá trị hao mòn lũy kế (*) | B16: ='BCTC du phong'!C78 -> -6224924000 | C16: ='BCTC du phong'!D78 -> -8006620000 | D16: ='BCTC du phong'!E78 -> -9254023000 | E16: ='BCTC du phong'!F78 -> -10390939000 | F16: ='BCTC du phong'!G78 -> -11716262000
F18: Khấu hao TSCĐ hiện có | G18: =IFERROR(SYD($F$4,0,$E$21,G1-$F$1),0) -> 5.0599331e+10 | H18: =IFERROR(SYD($F$4,0,$E$21,H1-$F$1),0) -> 4.7819914e+10 | I18: =IFERROR(SYD($F$4,0,$E$21,I1-$F$1),0) -> 4.5040497e+10 | J18: =IFERROR(SYD($F$4,0,$E$21,J1-$F$1),0) -> 4.2261079e+10 | K18: =IFERROR(SYD($F$4,0,$E$21,K1-$F$1),0) -> 3.9481662e+10 | L18: (Khấu hao nhanh)
A19: Khấu hao TSCD HH và VH | D19: Nguyên giá | E19: =AVERAGE(E4:F4)+AVERAGE(E15:F15) -> 528003783000 | F19: Khấu hao TSCĐ năm 2020 | G19: =SLN($G$8+$G$9,0,$E$21) -> 8.0239684e+08 | H19: =SLN($G$8+$G$9,0,$E$21) -> 8.0239684e+08 | I19: =SLN($G$8+$G$9,0,$E$21) -> 8.0239684e+08 | J19: =SLN($G$8+$G$9,0,$E$21) -> 8.0239684e+08 | K19: =SLN($G$8+$G$9,0,$E$21) -> 8.0239684e+08
D20: Khấu hao | E20: =AVERAGE('BCTC du phong'!F290:G290) -> 29003206000 | F20: Khấu hao TSCĐ năm 2021 | H20: =SLN($H$8+$H$9,0,$E$21) -> 1.5006589e+09 | I20: =SLN($H$8+$H$9,0,$E$21) -> 1.5006589e+09 | J20: =SLN($H$8+$H$9,0,$E$21) -> 1.5006589e+09 | K20: =SLN($H$8+$H$9,0,$E$21) -> 1.5006589e+09
D21: Vòng đời | E21: =MAX(E19/E20,5) -> 18.205014 | F21: Khấu hao TSCĐ năm 2022 | I21: =SLN($I$8+$I$9,0,$E$21) -> 8.2518218e+08 | J21: =SLN($I$8+$I$9,0,$E$21) -> 8.2518218e+08 | K21: =SLN($I$8+$I$9,0,$E$21) -> 8.2518218e+08
F22: Khấu hao TSCĐ năm 2023 | J22: =SLN($J$8+$J$9,0,$E$21) -> 1.5539802e+09 | K22: =SLN($J$8+$J$9,0,$E$21) -> 1.5539802e+09
F23: Khấu hao TSCĐ năm 2024 | K23: =SLN($K$8+$K$9,0,$E$21) -> 1.1361796e+09
A25: ='BCTC du phong'!B82 -> IV. Tài sản dở dang dài hạn | B25: ='BCTC du phong'!C82 -> 1869249000 | C25: ='BCTC du phong'!D82 -> 1379610000 | D25: ='BCTC du phong'!E82 -> 2464967000 | E25: ='BCTC du phong'!F82 -> 25264977000 | F25: ='BCTC du phong'!G82 -> 14607646000 | G25: =SUM(G26:G27) -> 2.7319517e+10 | H25: =SUM(H26:H27) -> 1.5022453e+10 | I25: =SUM(I26:I27) -> 2.8290233e+10 | J25: =SUM(J26:J27) -> 2.0684167e+10 | K25: =SUM(K26:K27) -> 4.2498808e+10
A26: ='BCTC du phong'!B83 -> 1. Chi phí sản xuất, kinh doanh dở dang dài hạn | B26: ='BCTC du phong'!C83 -> 0 | C26: ='BCTC du phong'!D83 -> 0 | D26: ='BCTC du phong'!E83 -> 0 | E26: ='BCTC du phong'!F83 -> 0 | F26: ='BCTC du phong'!G83 -> 0 | G26: 0 | H26: =G26 -> 0 | I26: =H26 -> 0 | J26: =I26 -> 0 | K26: =J26 -> 0
A27: ='BCTC du phong'!B84 -> 2. Chi phí xây dựng cơ bản dở dang | B27: ='BCTC du phong'!C84 -> 1869249000 | C27: ='BCTC du phong'!D84 -> 1379610000 | D27: ='BCTC du phong'!E84 -> 2464967000 | E27: ='BCTC du phong'!F84 -> 25264977000 | F27: ='BCTC du phong'!G84 -> 14607646000 | G27: =G32 -> 2.7319517e+10 | H27: =H32 -> 1.5022453e+10 | I27: =I32 -> 2.8290233e+10 | J27: =J32 -> 2.0684167e+10 | K27: =K32 -> 4.2498808e+10
A29: Đầu kì | C29: =B32 -> 1869249000 | D29: =C32 -> 1379610000 | E29: =D32 -> 2464967000 | F29: =E32 -> 25264977000 | G29: =F32 -> 14607646000 | H29: =G32 -> 2.7319517e+10 | I29: =H32 -> 1.5022453e+10 | J29: =I32 -> 2.8290233e+10 | K29: =J32 -> 2.0684167e+10
A30: Tăng thêm | G30: =-G35 -> 2.7319517e+10 | H30: =-H35 -> 1.5022453e+10 | I30: =-I35 -> 2.8290233e+10 | J30: =-J35 -> 2.0684167e+10 | K30: =-K35 -> 4.2498808e+10
A31: Chuyển xuống TSCĐ | G31: =-G29 -> -14607646000 | H31: =-H29 -> -2.7319517e+10 | I31: =-I29 -> -1.5022453e+10 | J31: =-J29 -> -2.8290233e+10 | K31: =-K29 -> -2.0684167e+10
A32: Cuối kì | B32: =B25 -> 1869249000 | C32: =C25 -> 1379610000 | D32: =D25 -> 2464967000 | E32: =E25 -> 25264977000 | F32: =F25 -> 14607646000 | G32: =SUM(G29:G31) -> 2.7319517e+10 | H32: =SUM(H29:H31) -> 1.5022453e+10 | I32: =SUM(I29:I31) -> 2.8290233e+10 | J32: =SUM(J29:J31) -> 2.0684167e+10 | K32: =SUM(K29:K31) -> 4.2498808e+10
A34: CAPEX
A35: Mua mới | B35: ='BCTC du phong'!C296 -> -15250990000 | C35: ='BCTC du phong'!D296 -> -12385353000 | D35: ='BCTC du phong'!E296 -> -16714009000 | E35: ='BCTC du phong'!F296 -> -41930046000 | F35: ='BCTC du phong'!G296 -> -35203196000 | G35: =IF('Doanh thu'!G6*TSCĐ!G36>('BCTC du phong'!H293+'BCTC du phong'!H318),-MIN($B$36:$F$36)*'Doanh thu'!G6,-'Doanh thu'!G6*TSCĐ!G36) -> -2.7319517e+10 | H35: =IF('Doanh thu'!H6*TSCĐ!H36>('BCTC du phong'!I293+'BCTC du phong'!I318),-MIN($B$36:$F$36)*'Doanh thu'!H6,-'Doanh thu'!H6*TSCĐ!H36) -> -1.5022453e+10 | I35: =IF('Doanh thu'!I6*TSCĐ!I36>('BCTC du phong'!J293+'BCTC du phong'!J318),-MIN($B$36:$F$36)*'Doanh thu'!I6,-'Doanh thu'!I6*TSCĐ!I36) -> -2.8290233e+10 | J35: =IF('Doanh thu'!J6*TSCĐ!J36>('BCTC du phong'!K293+'BCTC du phong'!K318),-MIN($B$36:$F$36)*'Doanh thu'!J6,-'Doanh thu'!J6*TSCĐ!J36) -> -2.0684167e+10 | K35: =IF('Doanh thu'!K6*TSCĐ!K36>('BCTC du phong'!L293+'BCTC du phong'!L318),-MIN($B$36:$F$36)*'Doanh thu'!K6,-'Doanh thu'!K6*TSCĐ!K36) -> -4.2498808e+10
A36: %doanh thu | B36: =-B35/'[1]BC Kết Quả Kinh Doanh'!C8 -> 0.012358678 | C36: =-C35/'[1]BC Kết Quả Kinh Doanh'!D8 -> 0.0096063049 | D36: =-D35/'[1]BC Kết Quả Kinh Doanh'!E8 -> 0.012476394 | E36: =-E35/'[1]BC Kết Quả Kinh Doanh'!F8 -> 0.030272467 | F36: =-F35/'[1]BC Kết Quả Kinh Doanh'!G8 -> 0.023974005 | G36: =AVERAGEIFS(C36:F36,C36:F36,$G$37,C36:F36,H37) -> 0.019082293 | H36: =AVERAGEIFS(D36:G36,D36:G36,$G$37,D36:G36,I37) -> 0.015779344 | I36: =AVERAGEIFS(E36:H36,E36:H36,$G$37,E36:H36,J37) -> 0.015779344 | J36: =AVERAGEIFS(F36:I36,F36:I36,$G$37,F36:I36,K37) -> 0.015779344 | K36: =AVERAGEIFS(G36:J36,G36:J36,$G$37,G36:J36,L37) -> 0.015779344
G37: =">="&MIN(C36:F36) -> >=0,00960630492322467 | H37: ="<"&MIN(C36:F36)*10 -> <0,0960630492322467 | I37: ="<="&G36 -> <=0,0190822927710484 | J37: ="<="&H36 -> <=0,0157793435504106 | K37: ="<="&I36 -> <=0,0157793435504106 | L37: ="<="&J36 -> <=0,0157793435504106

Sheet Vốn CSH
A1: Vốn chủ sở hữu | B1: ='[1]Bảng Cân Đối Kế Toán'!C5 -> 2015 | C1: ='[1]Bảng Cân Đối Kế Toán'!D5 -> 2016 | D1: ='[1]Bảng Cân Đối Kế Toán'!E5 -> 2017 | E1: ='[1]Bảng Cân Đối Kế Toán'!F5 -> 2018 | F1: ='[1]Bảng Cân Đối Kế Toán'!G5 -> 2019 | G1: =F1+1 -> 2020 | H1: =G1+1 -> 2021 | I1: =H1+1 -> 2022 | J1: =I1+1 -> 2023 | K1: =J1+1 -> 2024
A3: ='BCTC du phong'!B133 -> I. Vốn chủ sở hữu | B3: ='BCTC du phong'!C133 -> 793318496000 | C3: ='BCTC du phong'!D133 -> 883633401000 | D3: ='BCTC du phong'!E133 -> 952805914000 | E3: ='BCTC du phong'!F133 -> 1129539832000 | F3: ='BCTC du phong'!G133 -> 1252268690000 | G3: =G4+G9+G15+G18+G19+G20+G21+G22+G23+G24+G26+G41+G42+SUM(G43:G47) -> 1.3890991e+12 | H3: =H4+H9+H15+H18+H19+H20+H21+H22+H23+H24+H26+H41+H42+SUM(H43:H47) -> 1.5483669e+12 | I3: =I4+I9+I15+I18+I19+I20+I21+I22+I23+I24+I26+I41+I42+SUM(I43:I47) -> 1.7234757e+12 | J3: =J4+J9+J15+J18+J19+J20+J21+J22+J23+J24+J26+J41+J42+SUM(J43:J47) -> 1.9368244e+12 | K3: =K4+K9+K15+K18+K19+K20+K21+K22+K23+K24+K26+K41+K42+SUM(K43:K47) -> 2.1933797e+12
A4: ='BCTC du phong'!B134 -> 1. Vốn góp của chủ sở hữu | B4: ='BCTC du phong'!C134 -> 267137970000 | C4: ='BCTC du phong'!D134 -> 347274650000 | D4: ='BCTC du phong'!E134 -> 347274650000 | E4: ='BCTC du phong'!F134 -> 347274650000 | F4: ='BCTC du phong'!G134 -> 347274650000 | G4: =G5+G6 -> 347274650000 | H4: =H5+H6 -> 347274650000 | I4: =I5+I6 -> 347274650000 | J4: =J5+J6 -> 347274650000 | K4: =K5+K6 -> 347274650000
A5: ='BCTC du phong'!B135 -> - Cổ phiếu phổ thông có quyền biểu quyết | B5: ='BCTC du phong'!C135 -> 267137970000 | C5: ='BCTC du phong'!D135 -> 347274650000 | D5: ='BCTC du phong'!E135 -> 347274650000 | E5: ='BCTC du phong'!F135 -> 347274650000 | F5: ='BCTC du phong'!G135 -> 347274650000 | G5: =F5+G11*G12 -> 347274650000 | H5: =G5 -> 347274650000 | I5: =H5 -> 347274650000 | J5: =I5 -> 347274650000 | K5: =J5 -> 347274650000
A6: ='BCTC du phong'!B136 -> - Cổ phiếu ưu đãi | B6: ='BCTC du phong'!C136 -> 0 | C6: ='BCTC du phong'!D136 -> 0 | D6: ='BCTC du phong'!E136 -> 0 | E6: ='BCTC du phong'!F136 -> 0 | F6: ='BCTC du phong'!G136 -> 0 | G6: =F6 -> 0 | H6: =G6 -> 0 | I6: =H6 -> 0 | J6: =I6 -> 0 | K6: =J6 -> 0
A9: ='BCTC du phong'!B137 -> 2. Thặng dư vốn cổ phần | B9: ='BCTC du phong'!C137 -> 140470630000 | C9: ='BCTC du phong'!D137 -> 60333950000 | D9: ='BCTC du phong'!E137 -> 60333950000 | E9: ='BCTC du phong'!F137 -> 60333950000 | F9: ='BCTC du phong'!G137 -> 60333950000 | G9: =F9+G14 -> 60333950000 | H9: =G9 -> 60333950000 | I9: =H9 -> 60333950000 | J9: =I9 -> 60333950000 | K9: =J9 -> 60333950000
F11: Số cổ phần tăng thêm | G11: 0
F12: Mệnh giá | G12: 10000
F13: Giá bán | G13: 0
F14: Thặng dư vốn cổ phần tăng thêm | G14: =(G13-G12)*G11 -> 0
A15: ='BCTC du phong'!B138 -> 3. Quyền chọn chuyển đổi trái phiếu | B15: ='BCTC du phong'!C138 -> 0 | C15: ='BCTC du phong'!D138 -> 0 | D15: ='BCTC du phong'!E138 -> 0 | E15: ='BCTC du phong'!F138 -> 0 | F15: ='BCTC du phong'!G138 -> 0 | G15: =F15 -> 0 | H15: =G15 -> 0 | I15: =H15 -> 0 | J15: =I15 -> 0 | K15: =J15 -> 0
A18: ='BCTC du phong'!B139 -> 4. Vốn khác của chủ sở hữu | B18: ='BCTC du phong'!C139 -> 0 | C18: ='BCTC du phong'!D139 -> 0 | D18: ='BCTC du phong'!E139 -> 0 | E18: ='BCTC du phong'!F139 -> 0 | F18: ='BCTC du phong'!G139 -> 0 | G18: =F18 -> 0 | H18: =G18 -> 0 | I18: =H18 -> 0 | J18: =I18 -> 0 | K18: =J18 -> 0
A19: ='BCTC du phong'!B140 -> 5. Cổ phiếu quỹ (*) | B19: ='BCTC du phong'!C140 -> 0 | C19: ='BCTC du phong'!D140 -> 0 | D19: ='BCTC du phong'!E140 -> 0 | E19: ='BCTC du phong'!F140 -> 0 | F19: ='BCTC du phong'!G140 -> 0 | G19: =F19 -> 0 | H19: =G19 -> 0 | I19: =H19 -> 0 | J19: =I19 -> 0 | K19: =J19 -> 0
A20: ='BCTC du phong'!B141 -> 6. Chênh lệch đánh giá lại tài sản | B20: ='BCTC du phong'!C141 -> 0 | C20: ='BCTC du phong'!D141 -> 0 | D20: ='BCTC du phong'!E141 -> 0 | E20: ='BCTC du phong'!F141 -> 0 | F20: ='BCTC du phong'!G141 -> 0 | G20: =F20 -> 0 | H20: =G20 -> 0 | I20: =H20 -> 0 | J20: =I20 -> 0 | K20: =J20 -> 0
A21: ='BCTC du phong'!B142 -> 7. Chênh lệch tỷ giá hối đoái | B21: ='BCTC du phong'!C142 -> 0 | C21: ='BCTC du phong'!D142 -> 0 | D21: ='BCTC du phong'!E142 -> 0 | E21: ='BCTC du phong'!F142 -> 0 | F21: ='BCTC du phong'!G142 -> 0 | G21: =F21 -> 0 | H21: =G21 -> 0 | I21: =H21 -> 0 | J21: =I21 -> 0 | K21: =J21 -> 0
A22: ='BCTC du phong'!B143 -> 8. Quỹ đầu tư phát triển | B22: ='BCTC du phong'!C143 -> 243133032000 | C22: ='BCTC du phong'!D143 -> 306365742000 | D22: ='BCTC du phong'!E143 -> 389626549000 | E22: ='BCTC du phong'!F143 -> 493159585000 | F22: ='BCTC du phong'!G143 -> 612025497000 | G22: =G31 -> 730891409000 | H22: =H31 -> 8.5893636e+11 | I22: =I31 -> 1.0029348e+12 | J22: =J31 -> 1.1628293e+12 | K22: =K31 -> 1.3500365e+12
A23: ='BCTC du phong'!B144 -> 9. Quỹ hỗ trợ sắp xếp doanh nghiệp | B23: ='BCTC du phong'!C144 -> 0 | C23: ='BCTC du phong'!D144 -> 0 | D23: ='BCTC du phong'!E144 -> 0 | E23: ='BCTC du phong'!F144 -> 0 | F23: ='BCTC du phong'!G144 -> 0 | G23: =F23 -> 0 | H23: =G23 -> 0 | I23: =H23 -> 0 | J23: =I23 -> 0 | K23: =J23 -> 0
A24: ='BCTC du phong'!B145 -> 10. Quỹ khác thuộc vốn chủ sở hữu | B24: ='BCTC du phong'!C145 -> 0 | C24: ='BCTC du phong'!D145 -> 0 | D24: ='BCTC du phong'!E145 -> 0 | E24: ='BCTC du phong'!F145 -> 0 | F24: ='BCTC du phong'!G145 -> 0 | G24: =F24 -> 0 | H24: =G24 -> 0 | I24: =H24 -> 0 | J24: =I24 -> 0 | K24: =J24 -> 0
A26: ='BCTC du phong'!B146 -> 11. Lợi nhuận sau thuế chưa phân phối | B26: ='BCTC du phong'!C146 -> 142576864000 | C26: ='BCTC du phong'!D146 -> 169659059000 | D26: ='BCTC du phong'!E146 -> 155570765000 | E26: ='BCTC du phong'!F146 -> 228771647000 | F26: ='BCTC du phong'!G146 -> 232634592000 | G26: =G27+G28 -> 2.5059905e+11 | H26: =H27+H28 -> 2.8182195e+11 | I26: =I27+I28 -> 3.1293228e+11 | J26: =J27+J28 -> 3.6638655e+11 | K26: =K27+K28 -> 4.3573461e+11
A27: ='BCTC du phong'!B147 -> - LNST chưa phân phối lũy kế đến cuối kỳ trước | B27: ='BCTC du phong'!C147 -> 1017585000 | C27: ='BCTC du phong'!D147 -> 1017585000 | D27: ='BCTC du phong'!E147 -> 0 | E27: ='BCTC du phong'!F147 -> 0 | F27: ='BCTC du phong'!G147 -> 0 | G27: =F26 -> 232634592000 | H27: =G26 -> 2.5059905e+11 | I27: =H26 -> 2.8182195e+11 | J27: =I26 -> 3.1293228e+11 | K27: =J26 -> 3.6638655e+11
A28: ='BCTC du phong'!B148 -> - LNST chưa phân phối kỳ này | B28: ='BCTC du phong'!C148 -> 141559279000 | C28: ='BCTC du phong'!D148 -> 168641475000 | D28: ='BCTC du phong'!E148 -> 155570765000 | E28: ='BCTC du phong'!F148 -> 228771647000 | F28: ='BCTC du phong'!G148 -> 232634592000 | G28: =G30+G38-(G32)-(G35-F35) -> 1.7964457e+10 | H28: =H30+H38-(H32)-(H35-G35) -> 3.1222899e+10 | I28: =I30+I38-(I32)-(I35-H35) -> 3.111033e+10 | J28: =J30+J38-(J32)-(J35-I35) -> 5.3454269e+10 | K28: =K30+K38-(K32)-(K35-J35) -> 6.9348058e+10
A30: Lợi nhuận ròng | B30: ='BCTC du phong'!C22 -> 141559279000 | C30: ='BCTC du phong'!D22 -> 168641475000 | D30: ='BCTC du phong'!E22 -> 207661963000 | E30: ='BCTC du phong'!F22 -> 228771647000 | F30: ='BCTC du phong'!G22 -> 232634592000 | G30: ='BCTC du phong'!H22 -> 2.1940191e+11 | H30: ='BCTC du phong'!I22 -> 2.515875e+11 | I30: ='BCTC du phong'!J22 -> 2.8142671e+11 | ... K30: ='BCTC du phong'!L22 -> 4.124408e+11
A31: Trích quỹ đầu tư phát triển | B31: ='Vốn CSH'!B22 -> 243133032000 | C31: ='Vốn CSH'!C22 -> 306365742000 | D31: ='Vốn CSH'!D22 -> 389626549000 | E31: ='Vốn CSH'!E22 -> 493159585000 | F31: ='Vốn CSH'!F22 -> 612025497000 | G31: =F31+G32 -> 730891409000 | H31: =G31+H32 -> 8.5893636e+11 | I31: =H31+I32 -> 1.0029348e+12 | J31: =I31+J32 -> 1.1628293e+12 | K31: =J31+K32 -> 1.3500365e+12
A32: Thay đổi | C32: =C31-B31 -> 63232710000 | D32: =D31-C31 -> 83260807000 | E32: =E31-D31 -> 103533036000 | F32: =F31-E31 -> 118865912000 | G32: =G33*G27 -> 1.1886591e+11 | H32: =H33*H27 -> 1.2804495e+11 | I32: =I33*I27 -> 1.4399846e+11 | J32: =J33*J27 -> 1.5989445e+11 | K32: =K33*K27 -> 1.872072e+11
C33: =C32/C28 -> 0.37495349 | D33: =D32/D28 -> 0.53519572 | E33: =E32/E28 -> 0.45256061 | F33: =F32/F28 -> 0.51095545 | G33: =F33 -> 0.51095545 | H33: =G33 -> 0.51095545 | I33: =H33 -> 0.51095545 | J33: =I33 -> 0.51095545 | K33: =J33 -> 0.51095545
A34: % LNSTCPP | B34: =IFERROR(B31/B26,0) -> 1.7052769 | C34: =IFERROR(C31/C26,0) -> 1.805773 | D34: =IFERROR(D31/D26,0) -> 2.5044972 | E34: =IFERROR(E31/E26,0) -> 2.1556849 | F34: =IFERROR(F31/F26,0) -> 2.6308448 | G34: =IFERROR(G31/G26,0) -> 2.9165769 | H34: =IFERROR(H31/H26,0) -> 3.047798 | I34: =IFERROR(I31/I26,0) -> 3.204958 | ... K34: =IFERROR(K31/K26,0) -> 3.0982999
A35: Trích quỹ khen thưởng phúc lợi | B35: ='[1]Bảng Cân Đối Kế Toán'!C86 -> 1583413000 | C35: ='[1]Bảng Cân Đối Kế Toán'!D86 -> 394478000 | D35: ='[1]Bảng Cân Đối Kế Toán'!E86 -> 2299415000 | E35: ='[1]Bảng Cân Đối Kế Toán'!F86 -> 2290805000 | F35: ='[1]Bảng Cân Đối Kế Toán'!G86 -> 6985902000 | G35: =G36*G27 -> 6985902000 | H35: =H36*H27 -> 5.0173697e+09 | I35: =I36*I27 -> 5.6424991e+09 | J35: =J36*J27 -> 6.2653747e+09 | K35: =K36*K27 -> 7.3356095e+09
A36: % LNSTCPP | B36: =IFERROR(B35/B26,0) -> 0.01110568 | C36: =IFERROR(C35/C26,0) -> 0.0023251219 | D36: =IFERROR(D35/D26,0) -> 0.014780508 | E36: =IFERROR(E35/E26,0) -> 0.0100135 | F36: =IFERROR(F35/F26,0) -> 0.030029507 | G36: =F36 -> 0.030029507 | H36: =AVERAGE($E$36:$F$36) -> 0.020021504 | I36: =AVERAGE($E$36:$F$36) -> 0.020021504 | J36: =AVERAGE($E$36:$F$36) -> 0.020021504 | K36: =AVERAGE($E$36:$F$36) -> 0.020021504
A38: Cổ tức | B38: ='BCTC du phong'!C315 -> -48084835000 | C38: ='BCTC du phong'!D315 -> -53427594000 | D38: ='BCTC du phong'!E315 -> -69454915000 | E38: ='BCTC du phong'!F315 -> -86818627000 | F38: ='BCTC du phong'!G315 -> -86818663000 | G38: =-G39*G30 -> -8.2571539e+10 | H38: =-H39*H30 -> -9.4288189e+10 | I38: =-I39*I30 -> -1.0569279e+11 | J38: =-J39*J30 -> -1.2847434e+11 | K38: =-K39*K30 -> -1.5481531e+11
A39: Tỉ suất cổ tức | B39: =-B38/B30 -> 0.33967985 | C39: =-C38/C30 -> 0.31681171 | D39: =-D38/D30 -> 0.33446142 | E39: =-E38/E30 -> 0.37949907 | F39: =-F38/F30 -> 0.37319756 | G39: =AVERAGE(E39:F39) -> 0.37634832 | H39: =AVERAGE(F39:G39) -> 0.37477294 | I39: =AVERAGE(G39:H39) -> 0.37556063 | J39: =AVERAGE(H39:I39) -> 0.37516678 | K39: =AVERAGE(I39:J39) -> 0.37536371
A41: ='BCTC du phong'!B149 -> 12. Nguồn vốn đầu tư XDCB | B41: ='BCTC du phong'!C149 -> 0 | C41: ='BCTC du phong'!D149 -> 0 | D41: ='BCTC du phong'!E149 -> 0 | E41: ='BCTC du phong'!F149 -> 0 | F41: ='BCTC du phong'!G149 -> 0 | G41: =F41 -> 0 | H41: =G41 -> 0 | I41: =H41 -> 0 | J41: =I41 -> 0 | K41: =J41 -> 0
A42: ='BCTC du phong'!B150 -> 13. Lợi ích cổ đông không kiểm soát | B42: ='BCTC du phong'!C150 -> 0 | C42: ='BCTC du phong'!D150 -> 0 | D42: ='BCTC du phong'!E150 -> 0 | E42: ='BCTC du phong'!F150 -> 0 | F42: ='BCTC du phong'!G150 -> 0 | G42: =F42 -> 0 | H42: =G42 -> 0 | I42: =H42 -> 0 | J42: =I42 -> 0 | K42: =J42 -> 0
A43: ='BCTC du phong'!B151 -> 14. Quỹ dự phòng tài chính | B43: ='BCTC du phong'!C151 -> 0 | C43: ='BCTC du phong'!D151 -> 0 | D43: ='BCTC du phong'!E151 -> 0 | E43: ='BCTC du phong'!F151 -> 0 | F43: ='BCTC du phong'!G151 -> 0 | G43: =F43 -> 0 | H43: =G43 -> 0 | I43: =H43 -> 0 | J43: =I43 -> 0 | K43: =J43 -> 0
A44: ='BCTC du phong'!B152 -> II. Nguồn kinh phí và quỹ khác | B44: ='BCTC du phong'!C152 -> 0 | C44: ='BCTC du phong'!D152 -> 0 | D44: ='BCTC du phong'!E152 -> 0 | E44: ='BCTC du phong'!F152 -> 0 | F44: ='BCTC du phong'!G152 -> 0 | G44: =F44 -> 0 | H44: =G44 -> 0 | I44: =H44 -> 0 | J44: =I44 -> 0 | K44: =J44 -> 0
A45: ='BCTC du phong'!B153 -> 1. Nguồn kinh phí | B45: ='BCTC du phong'!C153 -> 0 | C45: ='BCTC du phong'!D153 -> 0 | D45: ='BCTC du phong'!E153 -> 0 | E45: ='BCTC du phong'!F153 -> 0 | F45: ='BCTC du phong'!G153 -> 0 | G45: =F45 -> 0 | H45: =G45 -> 0 | I45: =H45 -> 0 | J45: =I45 -> 0 | K45: =J45 -> 0
A46: ='BCTC du phong'!B154 -> 2. Nguồn kinh phí đã hình thành TSCĐ | B46: ='BCTC du phong'!C154 -> 0 | C46: ='BCTC du phong'!D154 -> 0 | D46: ='BCTC du phong'!E154 -> 0 | E46: ='BCTC du phong'!F154 -> 0 | F46: ='BCTC du phong'!G154 -> 0 | G46: =F46 -> 0 | H46: =G46 -> 0 | I46: =H46 -> 0 | J46: =I46 -> 0 | K46: =J46 -> 0
A47: ='BCTC du phong'!B155 -> C. LỢI ÍCH CỔ ĐÔNG THIỂU SỐ | B47: ='BCTC du phong'!C155 -> 0 | C47: ='BCTC du phong'!D155 -> 0 | D47: ='BCTC du phong'!E155 -> 0 | E47: ='BCTC du phong'!F155 -> 0 | F47: ='BCTC du phong'!G155 -> 0 | G47: =F47 -> 0 | H47: =G47 -> 0 | I47: =H47 -> 0 | J47: =I47 -> 0 | K47: =J47 -> 0

Sheet DT&CP tài chính
A1: DT & CP tài chính | B1: ='[1]Bảng Cân Đối Kế Toán'!C5 -> 2015 | C1: ='[1]Bảng Cân Đối Kế Toán'!D5 -> 2016 | D1: ='[1]Bảng Cân Đối Kế Toán'!E5 -> 2017 | E1: ='[1]Bảng Cân Đối Kế Toán'!F5 -> 2018 | F1: ='[1]Bảng Cân Đối Kế Toán'!G5 -> 2019 | G1: =F1+1 -> 2020 | H1: =G1+1 -> 2021 | I1: =H1+1 -> 2022 | J1: =I1+1 -> 2023 | K1: =J1+1 -> 2024
A3: DT tài chính | B3: ='BCTC du phong'!C8 -> 2069445000 | C3: ='BCTC du phong'!D8 -> 9650395000 | D3: ='BCTC du phong'!E8 -> 15862747000 | E3: ='BCTC du phong'!F8 -> 21072474000 | F3: ='BCTC du phong'!G8 -> 20007170000 | G3: =G34 -> 1.9088173e+10 | H3: =H34 -> 3.6491415e+10 | I3: =I34 -> 3.3596774e+10 | J3: =J34 -> 4.7407019e+10 | K3: =K34 -> 4.065668e+10
A4: Chi phí tài chính | B4: ='BCTC du phong'!C9 -> 2753785000 | C4: ='BCTC du phong'!D9 -> 6712827000 | D4: ='BCTC du phong'!E9 -> -595617000 | E4: ='BCTC du phong'!F9 -> 2523401000 | F4: ='BCTC du phong'!G9 -> 1353416000 | G4: =G15 -> 1.3091126e+09 | H4: =H15 -> 1.901854e+09 | I4: =I15 -> 1.785608e+09 | J4: =J15 -> 2.6497366e+09 | K4: =K15 -> 2.905354e+09
A6: Vay ngắn hạn | B6: ='BCTC du phong'!C112 -> 0 | C6: ='BCTC du phong'!D112 -> 0 | D6: ='BCTC du phong'!E112 -> 0 | E6: ='BCTC du phong'!F112 -> 23497576000 | F6: ='BCTC du phong'!G112 -> 0 | G6: =G8+G7 -> 0 | H6: =H8+H7 -> 0 | I6: =I8+I7 -> 0 | J6: =J8+J7 -> 0 | K6: =K8+K7 -> 0
A7: Vay thêm | G7: =IF(AND('Vốn lưu động'!$H$88>0,G19<200%),G19*'Vốn lưu động'!G88-F6,0) -> 2.2563563e+10 | H7: =IF(AND('Vốn lưu động'!$H$88>0,H19<200%),H19*'Vốn lưu động'!H88-G6,0) -> 3.2779916e+10 | I7: =IF(AND('Vốn lưu động'!$H$88>0,I19<200%),I19*'Vốn lưu động'!I88-H6,0) -> 3.0776328e+10 | J7: =IF(AND('Vốn lưu động'!$H$88>0,J19<200%),J19*'Vốn lưu động'!J88-I6,0) -> 4.5670249e+10 | K7: =IF(AND('Vốn lưu động'!$H$88>0,K19<200%),K19*'Vốn lưu động'!K88-J6,0) -> 5.007601e+10
A8: Trả nợ | F8: =-F7 -> 0 | G8: =-G7 -> -2.2563563e+10 | H8: =-H7 -> -3.2779916e+10 | I8: =-I7 -> -3.0776328e+10 | J8: =-J7 -> -4.5670249e+10 | K8: =-K7 -> -5.007601e+10
A10: Vay dài hạn | B10: ='BCTC du phong'!C125 -> 0 | C10: ='BCTC du phong'!D125 -> 0 | D10: ='BCTC du phong'!E125 -> 0 | E10: ='BCTC du phong'!F125 -> 0 | F10: ='BCTC du phong'!G125 -> 0 | G10: =F10+G11-G12 -> 0 | H10: =G10+H11-H12 -> 0 | I10: =H10+I11-I12 -> 0 | J10: =I10+J11-J12 -> 0 | K10: =J10+K11-K12 -> 0
A11: Vay thêm (+) | G11: =F10 -> 0 | H11: =G10 -> 0 | I11: =H10 -> 0 | J11: =I10 -> 0 | K11: =J10 -> 0
A12: Trả nợ (-) | G12: =F10 -> 0 | H12: =G10 -> 0 | I12: =H10 -> 0 | J12: =I10 -> 0 | K12: =J10 -> 0
A15: Lãi vay | B15: ='BCTC du phong'!C10 -> 0 | C15: ='BCTC du phong'!D10 -> 0 | D15: ='BCTC du phong'!E10 -> 0 | E15: ='BCTC du phong'!F10 -> 203969000 | F15: ='BCTC du phong'!G10 -> 1159334000 | G15: =(G10+G7)*G16 -> 1.3091126e+09 | H15: =(H10+H7)*H16 -> 1.901854e+09 | I15: =(I10+I7)*I16 -> 1.785608e+09 | J15: =(J10+J7)*J16 -> 2.6497366e+09 | K15: =(K10+K7)*K16 -> 2.905354e+09
A16: Lãi suất trung bình | F16: =IFERROR(AVERAGE(B15:F15)/(AVERAGE(B10:F10)+AVERAGE(B6:F6)),0) -> 0.058018878 | G16: =F16 -> 0.058018878 | H16: =G16 -> 0.058018878 | I16: =H16 -> 0.058018878 | J16: =I16 -> 0.058018878 | K16: =J16 -> 0.058018878
A19: Tỉ lệ nợ vay ngắn hạn/Nhu cầu vốn lưu động | B19: =B6/(('BCTC du phong'!C41+'BCTC du phong'!C50+'BCTC du phong'!C53)-('BCTC du phong'!C102-'BCTC du phong'!C112)) -> 0 | C19: =C6/(('BCTC du phong'!D41+'BCTC du phong'!D50+'BCTC du phong'!D53)-('BCTC du phong'!D102-'BCTC du phong'!D112)) -> 0 | D19: =D6/(('BCTC du phong'!E41+'BCTC du phong'!E50+'BCTC du phong'!E53)-('BCTC du phong'!E102-'BCTC du phong'!E112)) -> 0 | E19: =E6/(('BCTC du phong'!F41+'BCTC du phong'!F50+'BCTC du phong'!F53)-('BCTC du phong'!F102-'BCTC du phong'!F112)) -> 0.042630604 | F19: =F6/(('BCTC du phong'!G41+'BCTC du phong'!G50+'BCTC du phong'!G53)-('BCTC du phong'!G102-'BCTC du phong'!G112)) -> 0 | G19: =E19 -> 0.042630604 | H19: =G19 -> 0.042630604 | I19: =H19 -> 0.042630604 | J19: =I19 -> 0.042630604 | K19: =J19 -> 0.042630604
A21: 1 | B21: Dự phóng tiền mặt
A22: + | B22: Tiền mặt đầu kì | F22: ='BCTC du phong'!F323 -> 79508403000 | G22: ='BCTC du phong'!G323 -> 98367152000 | H22: ='BCTC du phong'!H323 -> 3.9759099e+11 | I22: ='BCTC du phong'!I323 -> 3.5034249e+11 | J22: ='BCTC du phong'!J323 -> 5.9295374e+11 | K22: ='BCTC du phong'!K323 -> 4.8381289e+11
A23: + | B23: Tiền thu vào trong kì | F23: ='BCTC du phong'!G320 -> 18858749000 | G23: ='BCTC du phong'!H320 -> 2.9922384e+11 | H23: ='BCTC du phong'!I320 -> -4.7248499e+10 | I23: ='BCTC du phong'!J320 -> 2.4261125e+11 | J23: ='BCTC du phong'!K320 -> -1.0914086e+11 | K23: ='BCTC du phong'!L320 -> 1.5707937e+11
